Workbook

Sheet Summary
A1: TENNISSA: Initial Two-Year Budget
A2: Tennessee Islamic School Scholarship Alliance, Inc. · Draft for Board review · Prepared October 2026
A4: Key figure | B4: Year 1 (FY2027) | C4: Year 2 (FY2028) | D4: 2-year total
A5: Section 25F contributions | B5: =Budget!B7 -> 168000 | C5: =Budget!C7 -> 375000 | D5: =B5+C5 -> 543000
A6: Scholarship pool (90% or more of 25F income) | B6: =Budget!B11 -> 152712 | C6: =Budget!C11 -> 342249.41 | D6: =B6+C6 -> 494961.41
A7: Scholarships paid to schools | B7: =-Budget!B14 -> 76356 | C7: =-Budget!C14 -> 247480.7 | D7: =B7+C7 -> 323836.7
A8: Students funded (estimate) | B8: =Budget!B16 -> 76 | C8: =Budget!C16 -> 155 | D8: =B8+C8 -> 231
A9: Meets 25F minimum students? | B9: =Budget!B17 -> Yes | C9: =Budget!C17 -> Yes
A10: Section 25F closing balance | B10: =Budget!B15 -> 76356 | C10: =Budget!C15 -> 171124.7
A11: Total operating revenue | B11: =Budget!B24 -> 41968 | C11: =Budget!C24 -> 65527.712 | D11: =B11+C11 -> 107495.71
A12: Total operating expenses | B12: =Budget!B77 -> 57750 | C12: =Budget!C77 -> 69861.75 | D12: =B12+C12 -> 127611.75
A13: Operating surplus (deficit) | B13: =Budget!B80 -> -15782 | C13: =Budget!C80 -> -4334.038 | D13: =B13+C13 -> -20116.038
A14: Closing operating cash (reserve) | B14: =Budget!B82 -> -15782 | C14: =Budget!C82 -> -20116.038
A16: 90% scholarship-spending check (by gift year)
A17: Gift-year group | B17: 25F income | C17: Scholarships paid by Dec 31, 2028 | D17: % spent
A18: 2027 gifts | B18: =Budget!B9 -> 169680 | C18: =-(Budget!B12+Budget!C13) -> 152712 | D18: =IFERROR(C18/B18,0) -> 0.9
A19: 2028 gifts | B19: =Budget!C9 -> 380277.12 | C19: =-Budget!C12 -> 171124.7 | D19: =IFERROR(C19/B19,0) -> 0.45
A20: 2027 gifts are fully committed by the end of 2028 (90% to scholarships, 10% admin). 2028 gifts have spring 2029 payments still to come, well within the deadline. Confirm the exact deadline with the CPA (FIN-001 §6.3).
A22: How to read this workbook
A23: • Change donor counts, average gift and other drivers on the Assumptions tab (blue and yellow cells). Everything else recalculates.
A24: • Operating Budget tab: operating costs by category (professional services, platforms, promotional, travel, staff and added items) and how they are funded.
A25: • Budget tab: line-by-line detail, with the Section 25F Scholarship Account and Operating Fund shown separately, as FIN-001 requires.
A26: • Scenarios tab: low, base and high donor cases side by side.
A27: • Notes tab: sources, key rules and items that need quotes.

Sheet Operating Budget
A1: TENNISSA Operating Budget by Category
A2: Category totals pulled from the Budget tab. (*) = category added beyond the requested list.
A4: Category | B4: Year 1 (FY2027) | C4: Year 2 (FY2028) | D4: 2-year total | E4: % of Year 2 | F4: Year 2 monthly avg
A5: 1. Professional services | B5: =Budget!B32 -> 17000 | C5: =Budget!C32 -> 16500 | D5: =B5+C5 -> 33500 | E5: =IFERROR(C5/C$14,0) -> 0.23618074 | F5: =C5/12 -> 1375
A6: 2. Platforms and technology | B6: =Budget!B42 -> 12690 | C6: =Budget!C42 -> 16365 | D6: =B6+C6 -> 29055 | E6: =IFERROR(C6/C$14,0) -> 0.23424835 | F6: =C6/12 -> 1363.75
A7: 3. Promotional | B7: =Budget!B48 -> 5500 | C7: =Budget!C48 -> 6900 | D7: =B7+C7 -> 12400 | E7: =IFERROR(C7/C$14,0) -> 0.098766492 | F7: =C7/12 -> 575
A8: 4. Travel | B8: =Budget!B51 -> 1500 | C8: =Budget!C51 -> 2000 | D8: =B8+C8 -> 3500 | E8: =IFERROR(C8/C$14,0) -> 0.028627969 | F8: =C8/12 -> 166.66667
A9: 5. Operational staff | B9: =Budget!B56 -> 12150 | C9: =Budget!C56 -> 18100 | D9: =B9+C9 -> 30250 | E9: =IFERROR(C9/C$14,0) -> 0.25908312 | F9: =C9/12 -> 1508.3333
A10: 6. Insurance (*) | B10: =Budget!B62 -> 3900 | C10: =Budget!C62 -> 4200 | D10: =B10+C10 -> 8100 | E10: =IFERROR(C10/C$14,0) -> 0.060118735 | F10: =C10/12 -> 350
A11: 7. Registrations and government fees (*) | B11: =Budget!B69 -> 920 | C11: =Budget!C69 -> 330 | D11: =B11+C11 -> 1250 | E11: =IFERROR(C11/C$14,0) -> 0.0047236149 | F11: =C11/12 -> 27.5
A12: 8. Office and administration (*) | B12: =Budget!B74 -> 1340 | C12: =Budget!C74 -> 2140 | D12: =B12+C12 -> 3480 | E12: =IFERROR(C12/C$14,0) -> 0.030631927 | F12: =C12/12 -> 178.33333
A13: Contingency | B13: =Budget!B76 -> 2750 | C13: =Budget!C76 -> 3326.75 | D13: =B13+C13 -> 6076.75 | E13: =IFERROR(C13/C$14,0) -> 0.047619048 | F13: =C13/12 -> 277.22917
A14: Total operating expenses | B14: =SUM(B5:B13) -> 57750 | C14: =SUM(C5:C13) -> 69861.75 | D14: =SUM(D5:D13) -> 127611.75 | E14: =IFERROR(C14/C$14,0) -> 1 | F14: =C14/12 -> 5821.8125
A16: Funded by
A17: Admin allocation from Section 25F (10%) | B17: =Budget!B20 -> 16968 | C17: =Budget!C20 -> 38027.712 | D17: =B17+C17 -> 54995.712
A18: Founder and Board operating gifts | B18: =Budget!B21 -> 15000 | C18: =Budget!C21 -> 7500 | D18: =B18+C18 -> 22500
A19: Community operating gifts and events | B19: =Budget!B22 -> 10000 | C19: =Budget!C22 -> 15000 | D19: =B19+C19 -> 25000
A20: Foundation grants | B20: =Budget!B23 -> 0 | C20: =Budget!C23 -> 5000 | D20: =B20+C20 -> 5000
A21: Total operating revenue | B21: =Budget!B24 -> 41968 | C21: =Budget!C24 -> 65527.712 | D21: =B21+C21 -> 107495.71
A22: Surplus (funding gap) | B22: =Budget!B80 -> -15782 | C22: =Budget!C80 -> -4334.038 | D22: =B22+C22 -> -20116.038

Sheet Assumptions
A1: TENNISSA Initial Budget: Assumptions
A2: Blue = input you can change. Yellow = key driver. Year 1 = startup through Dec 31, 2027 (FY2027); Year 2 = calendar 2028 (FY2028). All figures are planning estimates.
A4: Assumption | B4: Year 1 (FY2027) | C4: Year 2 (FY2028) | D4: Basis / note
A5: Section 25F scholarship contributions
A6: Credit-eligible individual donors (count) | B6: 120 | C6: 250 | D6: Planning estimate. Year 1 starts Jan 1, 2027 and only after TDOE listing and IRS registration.
A7: Average Section 25F gift ($) | B7: 1400 | C7: 1500 | D7: Credit cap is $1,700 per taxpayer; joint filers can give $1,700 each. Many donors will give less.
A8: Interest rate on Section 25F balance | B8: 0.02 | C8: 0.02 | D8: Insured deposit account (FIN-001 §6.4). Applied to opening balance plus half of the year's gifts.
A9: Administrative allocation from Section 25F income | B9: 0.1 | C9: 0.1 | D9: At least 90% of 25F income must fund scholarships, so admin is at most 10%. Payment processing fees on 25F gifts come out of this. Confirm treatment with CPA.
A10: Payment processing fees (% of 25F gifts) | B10: 0.025 | C10: 0.025 | D10: Blended card/ACH rate for nonprofit processing. ACH is cheaper; encourage it.
A11: Share of each year's scholarship pool paid in the fall (same year) | B11: 0.5 | C11: 0.5 | D11: Awards for the school year starting each August: fall semester paid that year, spring paid the next year.
A12: Average scholarship award ($) | B12: 2000 | C12: 2200 | D12: Last-dollar award after any EFS/ESA (SCH-001 §4.4). Used only to estimate the number of students funded.
A14: Operating revenue (not credit-eligible)
A15: Founder and Board operating gifts ($) | B15: 15000 | C15: 7500 | D15: Seed money. Startup costs before Jan 2027 cannot be paid from Section 25F funds, which do not exist yet.
A16: Community operating gifts and events ($) | B16: 10000 | C16: 15000 | D16: Masjid and community campaigns, dinner tickets (net of the quid-pro-quo value), business sponsors. Not credit-eligible.
A17: Foundation grants for operations ($) | B17: 0 | C17: 5000 | D17: Conservative; no grant assumed in Year 1.
A18: Opening operating cash, Year 1 ($) | B18: 0 | D18: Year 2 opening = Year 1 closing (calculated).
A20: Operational staff
A21: Number of operational staff | B21: 2 | C21: 3 | D21: Assumed headcount, adjust as needed. Contractors paid $600+ in a year need a W-9 and Form 1099-NEC. If a director receives a stipend, it is compensation and must be approved by disinterested directors (COI-001 §11).
A22: Stipend per person per month ($) | B22: 500 | C22: 500 | D22: Owner-provided rate (updated Oct 29, 2026 from $250).
A23: Months paid in the year | B23: 12 | C23: 12 | D23: Year 1 could start later (e.g., 10 months if staff begin in March 2027).
A25: Other
A26: Contingency (% of operating expenses) | B26: 0.05 | C26: 0.05 | D26: Unplanned costs, quotes higher than expected.
A27: Minimum students required by Section 25F | B27: 10 | C27: 10 | D27: Scholarships must reach at least this many students, at more than one school.

Sheet Budget
A1: TENNISSA Two-Year Budget: FY2027 and FY2028
A2: Two funds kept separate, as the law requires: the Section 25F Scholarship Account (restricted) and the Operating Fund. Green = pulled from Assumptions. Blue = input.
A4: Line item | B4: Year 1 (FY2027) | C4: Year 2 (FY2028) | D4: 2-year total | E4: Basis / note
A5: A. SECTION 25F SCHOLARSHIP ACCOUNT (restricted)
A6: Opening balance | B6: =0 -> 0 | C6: =B15 -> 76356 | E6: New account opened Dec 2026.
A7: Section 25F contributions | B7: =Assumptions!$B$6*Assumptions!$B$7 -> 168000 | C7: =Assumptions!$C$6*Assumptions!$C$7 -> 375000 | D7: =B7+C7 -> 543000 | E7: Donors × average gift. Cash from individuals only (DON-001 §3).
A8: Interest earned | B8: =Assumptions!$B$8*(B6+B7/2) -> 1680 | C8: =Assumptions!$C$8*(C6+C7/2) -> 5277.12 | D8: =B8+C8 -> 6957.12 | E8: Interest counts as 25F income and stays in the account.
A9: Total Section 25F income | B9: =B7+B8 -> 169680 | C9: =C7+C8 -> 380277.12 | D9: =B9+C9 -> 549957.12
A10: Less: administrative allocation to Operating Fund | B10: =-Assumptions!$B$9*B9 -> -16968 | C10: =-Assumptions!$C$9*C9 -> -38027.712 | D10: =B10+C10 -> -54995.712 | E10: At most 10% of income. Moved to the Operating Fund to pay costs, including processing fees.
A11: Scholarship pool from this year's income | B11: =B9+B10 -> 152712 | C11: =C9+C10 -> 342249.41 | D11: =B11+C11 -> 494961.41 | E11: Funds awards for the school year that starts in August of this year.
A12: Scholarships paid: fall semester (this year's pool) | B12: =-B11*Assumptions!$B$11 -> -76356 | C12: =-C11*Assumptions!$C$11 -> -171124.7 | D12: =B12+C12 -> -247480.7 | E12: Paid directly to schools after enrollment is confirmed (SCH-001 §7.2).
A13: Scholarships paid: spring semester (prior year's pool) | B13: =0 -> 0 | C13: =-B11*(1-Assumptions!$B$11) -> -76356 | D13: =B13+C13 -> -76356 | E13: Spring 2028 payments for 2027–28 awards.
A14: Total scholarships paid | B14: =B12+B13 -> -76356 | C14: =C12+C13 -> -247480.7 | D14: =B14+C14 -> -323836.7
A15: Closing balance (committed to next spring's payments) | B15: =B6+B9+B10+B14 -> 76356 | C15: =C6+C9+C10+C14 -> 171124.7 | E15: Should equal the unpaid spring share of this year's pool, plus any interest.
A16: Students funded (estimate) | B16: =IFERROR(ROUNDDOWN(B11/Assumptions!$B$12,0),0) -> 76 | C16: =IFERROR(ROUNDDOWN(C11/Assumptions!$C$12,0),0) -> 155 | E16: Pool ÷ average award. Students at more than one school are required.
A17: Meets Section 25F minimum number of students? | B17: =IF(B16>=Assumptions!$B$27,"Yes","No: below minimum") -> Yes | C17: =IF(C16>=Assumptions!$C$27,"Yes","No: below minimum") -> Yes
A19: B. OPERATING FUND: REVENUE
A20: Administrative allocation from Section 25F | B20: =-B10 -> 16968 | C20: =-C10 -> 38027.712 | D20: =B20+C20 -> 54995.712
A21: Founder and Board operating gifts | B21: =Assumptions!$B$15 -> 15000 | C21: =Assumptions!$C$15 -> 7500 | D21: =B21+C21 -> 22500
A22: Community operating gifts and events | B22: =Assumptions!$B$16 -> 10000 | C22: =Assumptions!$C$16 -> 15000 | D22: =B22+C22 -> 25000
A23: Foundation grants | B23: =Assumptions!$B$17 -> 0 | C23: =Assumptions!$C$17 -> 5000 | D23: =B23+C23 -> 5000
A24: Total operating revenue | B24: =SUM(B20:B23) -> 41968 | C24: =SUM(C20:C23) -> 65527.712 | D24: =B24+C24 -> 107495.71
A26: C. OPERATING FUND: EXPENSES
A27: 1. Professional services
A28: CPA consultation (setup, advice, Form 990 preparation) | B28: 2000 | C28: 3500 | D28: =B28+C28 -> 5500 | E28: Requested line. Year 1: chart of accounts, 25F fund setup, 90% tracker. Year 2: FY2027 Form 990 and the Section 25F schedule.
A29: Nonprofit consultation | B29: 3000 | C29: 1500 | D29: =B29+C29 -> 4500 | E29: Requested line. SGO setup, Form 1023 support, TDOE application, board training. Estimate; get a fixed-fee quote.
A30: Legal counsel (*) | B30: 4000 | C30: 1500 | D30: =B30+C30 -> 5500 | E30: Added. Charter, bylaws §4.4 review, policy sign-off, contracts (FACTS, schools). A consultant cannot give legal opinions.
A31: Independent audit or review, Section 25F (*) | B31: 8000 | C31: 10000 | D31: =B31+C31 -> 18000 | E31: Added. Annual audit required for SGOs; a reduced scope may apply to smaller SGOs. Get quotes.
A32: Subtotal: 1. professional services | B32: =SUM(B28:B31) -> 17000 | C32: =SUM(C28:C31) -> 16500 | D32: =SUM(D28:D31) -> 33500
A33: 2. Platforms and technology
A34: SGO management platform fee (FACTS Compass) | B34: 7500 | C34: 6000 | D34: =B34+C34 -> 13500 | E34: Requested line. PLACEHOLDER: request a written quote. Year 1 includes setup and configuration.
A35: Accounting platform | B35: 500 | C35: 500 | D35: =B35+C35 -> 1000 | E35: Requested line. Nonprofit accounting subscription with fund tracking (discounts through TechSoup).
A36: Payment processing fees on 25F gifts (*) | B36: =Assumptions!$B$10*B7 -> 4200 | C36: =Assumptions!$C$10*C7 -> 9375 | D36: =B36+C36 -> 13575 | E36: Added. % of 25F gifts (card/ACH). Paid from the administrative allocation.
A37: Website hosting and domain (IONOS) (*) | B37: 150 | C37: 150 | D37: =B37+C37 -> 300 | E37: Added. Current hosting plan.
A38: Website form service (Formspree) (*) | B38: 120 | C38: 120 | D38: =B38+C38 -> 240 | E38: Added. $0 on the free tier.
A39: Email and productivity (*) | B39: 0 | C39: 0 | D39: =B39+C39 -> 0 | E39: Added. Google Workspace for Nonprofits is free for eligible 501(c)(3)s.
A40: Phone and virtual number (*) | B40: 120 | C40: 120 | D40: =B40+C40 -> 240 | E40: Added. Public phone line for families and donors.
A41: Password manager and security tools (*) | B41: 100 | C41: 100 | D41: =B41+C41 -> 200 | E41: Added. MFA and password manager for all users (PRIV-001 §5).
A42: Subtotal: 2. platforms and technology | B42: =SUM(B34:B41) -> 12690 | C42: =SUM(C34:C41) -> 16365 | D42: =SUM(D34:D41) -> 29055
A43: 3. Promotional
...

Sheet Scenarios
A1: Donor scenarios (Year 1 and Year 2)
A2: Low and high cases are blue inputs. Base pulls from Assumptions. Operating costs other than processing fees are held at the Budget amounts.
A4: Measure | B4: Low Y1 | C4: Low Y2 | D4: Base Y1 | E4: Base Y2 | F4: High Y1 | G4: High Y2
A5: Donors | B5: 60 | C5: 120 | D5: =Assumptions!$B$6 -> 120 | E5: =Assumptions!$C$6 -> 250 | F5: 200 | G5: 400
A6: Average gift | B6: 1200 | C6: 1300 | D6: =Assumptions!$B$7 -> 1400 | E6: =Assumptions!$C$7 -> 1500 | F6: 1500 | G6: 1600
A7: Section 25F contributions (excl. interest) | B7: =B5*B6 -> 72000 | C7: =C5*C6 -> 156000 | D7: =D5*D6 -> 168000 | E7: =E5*E6 -> 375000 | F7: =F5*F6 -> 300000 | G7: =G5*G6 -> 640000
A8: Admin allocation (to operations) | B8: =Assumptions!$B$9*B7 -> 7200 | C8: =Assumptions!$C$9*C7 -> 15600 | D8: =Assumptions!$B$9*D7 -> 16800 | E8: =Assumptions!$C$9*E7 -> 37500 | F8: =Assumptions!$B$9*F7 -> 30000 | G8: =Assumptions!$C$9*G7 -> 64000
A9: Scholarship pool | B9: =B7-B8 -> 64800 | C9: =C7-C8 -> 140400 | D9: =D7-D8 -> 151200 | E9: =E7-E8 -> 337500 | F9: =F7-F8 -> 270000 | G9: =G7-G8 -> 576000
A10: Students funded (estimate) | B10: =IFERROR(ROUNDDOWN(B9/Assumptions!$B$12,0),0) -> 32 | C10: =IFERROR(ROUNDDOWN(C9/Assumptions!$C$12,0),0) -> 63 | D10: =IFERROR(ROUNDDOWN(D9/Assumptions!$B$12,0),0) -> 75 | E10: =IFERROR(ROUNDDOWN(E9/Assumptions!$C$12,0),0) -> 153 | F10: =IFERROR(ROUNDDOWN(F9/Assumptions!$B$12,0),0) -> 135 | G10: =IFERROR(ROUNDDOWN(G9/Assumptions!$C$12,0),0) -> 261
A11: Operating revenue | B11: =B8+Budget!B21+Budget!B22+Budget!B23 -> 32200 | C11: =C8+Budget!C21+Budget!C22+Budget!C23 -> 43100 | D11: =D8+Budget!B21+Budget!B22+Budget!B23 -> 41800 | E11: =E8+Budget!C21+Budget!C22+Budget!C23 -> 65000 | F11: =F8+Budget!B21+Budget!B22+Budget!B23 -> 55000 | G11: =G8+Budget!C21+Budget!C22+Budget!C23 -> 91500
A12: Operating expenses (incl. contingency) | B12: =(Budget!B75-Budget!B36+Assumptions!$B$10*B7)*(1+Assumptions!$B$26) -> 55230 | C12: =(Budget!C75-Budget!C36+Assumptions!$C$10*C7)*(1+Assumptions!$C$26) -> 64113 | D12: =(Budget!B75-Budget!B36+Assumptions!$B$10*D7)*(1+Assumptions!$B$26) -> 57750 | E12: =(Budget!C75-Budget!C36+Assumptions!$C$10*E7)*(1+Assumptions!$C$26) -> 69861.75 | F12: =(Budget!B75-Budget!B36+Assumptions!$B$10*F7)*(1+Assumptions!$B$26) -> 61215 | G12: =(Budget!C75-Budget!C36+Assumptions!$C$10*G7)*(1+Assumptions!$C$26) -> 76818
A13: Operating surplus (deficit) | B13: =B11-B12 -> -23030 | C13: =C11-C12 -> -21013 | D13: =D11-D12 -> -15950 | E13: =E11-E12 -> -4861.75 | F13: =F11-F12 -> -6215 | G13: =G11-G12 -> 14682
A15: Takeaway: at low donor volume the 10% admin allocation does not cover fixed costs (audit, platform, insurance), so founders and community operating gifts carry the organization. Raise operating gifts or cut fixed costs before the low case happens.

Sheet Notes
A1: Notes, rules and sources
A3: Rules built into this budget
A4: Separate funds | B4: Section 25F gifts are held in a separate account and never used for salaries beyond the permitted admin share (FIN-001 §6, §11).
A5: 90% rule | B5: At least 90% of Section 25F income must fund scholarships for eligible students within the required period. The admin share is capped at 10% and must cover processing fees.
A6: Credit-eligible gifts | B6: Only cash gifts from individuals, made on or after Jan 1, 2027, after TDOE listing and IRS SGO registration. Corporate, noncash and event revenue go to the Operating Fund.
A7: Startup costs | B7: Costs before Jan 2027 (charter, Form 1023, legal, platform setup, insurance) must be paid from founder or community operating gifts, not 25F funds.
A8: Compensation | B8: No revenue-based or percentage pay. Any Executive Director pay is a fixed amount approved by disinterested directors (COI-001 §11).
A9: Items that need quotes
A10: FACTS Compass | B10: Platform pricing is a placeholder. Request a written quote, including setup, per-transaction fees and donor statement features.
A11: Insurance | B11: D&O, crime, general liability and cyber amounts are estimates. Get broker quotes.
A12: Audit | B12: Get quotes from CPA firms with nonprofit experience. Confirm the Section 25F audit scope and any small-SGO option.
A13: Fees to confirm | B13: TN charter, annual report and charitable solicitation fees, and the IRS Form 1023 user fee, should be confirmed on the official sites before payment.
A14: Sources
A15: TN charitable solicitation | B15: Registration fees and the $50,000 exemption threshold: https://www.harborcompliance.com/information/tennessee-charitable-registration (third-party summary; confirm with the TN Secretary of State).
A16: Federal law | B16: IRC § 25F; IRS Notice 2025-70; Treasury regulations. Check irs.gov for current guidance.
A17: TENNISSA policies | B17: FIN-001 Financial Controls; SCH-001 Scholarship; DON-001 Donor Acceptance; SGO-001 Section 25F Compliance (tennissa-policies repository).
A18: Disclaimer | B18: Planning estimates for Board discussion. Not accounting, tax or legal advice. Have the CPA review before adoption.
